<?xml version="1.0"?>
<robot xmlns:xacro="http://ros.org/wiki/xacro">

<!--
  Author: Felix Messmer
-->

  <xacro:include filename="$(find mara_description)/urdf/mara.transmission.xacro" />
  <xacro:include filename="$(find mara_description)/urdf/mara.gazebo.xacro" />

  <xacro:macro name="mara_robot"  params="prefix joint_limited">

    <link name="${prefix}base_link">
      <inertial>
        <origin rpy="0 0 0" xyz="8.625E-08 -4.6583E-06 0.03145"/>
        <mass value="7.033"/>
        <inertia ixx="0.1478344" ixy="-0.00001" ixz="0.0" iyy="0.14782335" iyz="0.0" izz="0.29471799"/>
      </inertial>
      <visual>
        <origin rpy="0 0 0" xyz="0 0 0"/>
        <geometry>
          <mesh filename="package://mara_description/meshes/H-ROS_Robot_BASE.stl" scale="0.001 0.001 0.001"/>
        </geometry>
        <material name="Gazebo/Grey">
          <color rgba="0. 0. 0. 1"/>
        </material>
      </visual>
      <collision>
        <origin rpy="0 0 0" xyz="0 0 0"/>
        <geometry>
          <mesh filename="package://mara_description/meshes/H-ROS_Robot_BASE.stl" scale="0.001 0.001 0.001"/>
        </geometry>
      </collision>
    </link>
    <gazebo reference="${prefix}base_link">
      <material>Gazebo/Grey</material>
      <selfCollide>False</selfCollide>
    </gazebo>

    <link name="${prefix}motor1_link">
      <inertial>
        <origin rpy="0 0 0" xyz="8.625E-08 -4.6583E-06 0.03145"/>
        <mass value="5.8"/>
        <inertia ixx="0.10105893" ixy="0.000211" ixz="-0.004" iyy="0.09386624" iyz="-0.01698537" izz="0.01449937"/>
      </inertial>
      <visual>
        <origin rpy="0 0 0" xyz="0 0 0"/>
        <geometry>
          <mesh filename="package://mara_description/meshes/H-ROS_Robot_mara1.stl" scale="0.001 0.001 0.001"/>
        </geometry>
        <material name="Gazebo/White">
          <color rgba="0. 0. 0. 1"/>
        </material>
      </visual>
      <collision>
        <origin rpy="0 0 0" xyz="0 0 0"/>
        <geometry>
          <mesh filename="package://mara_description/meshes/H-ROS_Robot_mara1.stl" scale="0.001 0.001 0.001"/>
        </geometry>
      </collision>
    </link>
    <gazebo reference="${prefix}motor1_link">
      <material>Gazebo/White</material>
      <selfCollide>False</selfCollide>
    </gazebo>

    <link name="${prefix}motor2_link">
      <inertial>
        <origin rpy="0 0 0" xyz="8.625E-08 -4.6583E-06 0.03145"/>
        <mass value="1.03237"/>
        <inertia ixx="0.014865226" ixy="0.0" ixz="0.0" iyy="0.01557" iyz="0.00071" izz="0.00092"/>
      </inertial>
      <visual>
        <origin rpy="0 0 0" xyz="0 0 0"/>
        <geometry>
          <mesh filename="package://mara_description/meshes/H-ROS_Robot_LINK1.stl" scale="0.001 0.001 0.001"/>
        </geometry>
        <material name="Gazebo/Black">
          <color rgba="0. 0. 0. 1"/>
        </material>
      </visual>
      <collision>
        <origin rpy="0 0 0" xyz="0 0 0"/>
        <geometry>
          <mesh filename="package://mara_description/meshes/H-ROS_Robot_LINK1.stl" scale="0.001 0.001 0.001"/>
        </geometry>
      </collision>
    </link>
    <gazebo reference="${prefix}motor2_link">
      <material>Gazebo/Black</material>
      <selfCollide>False</selfCollide>
    </gazebo>

    <link name="${prefix}motor3_link">
      <inertial>
        <origin rpy="0 0 0" xyz="8.625E-08 -4.6583E-06 0.03145"/>
        <mass value="3.8"/>
        <inertia ixx="0.04517" ixy="0.00002" ixz="0.0" iyy="0.01587" iyz="0.01444" izz="0.03303"/>
      </inertial>
      <visual>
        <origin rpy="0 0 0" xyz="0 0 0"/>
        <geometry>
          <mesh filename="package://mara_description/meshes/H-ROS_Robot_mara2.stl" scale="0.001 0.001 0.001"/>
        </geometry>
        <material name="Gazebo/White">
          <color rgba="0. 0. 0. 1"/>
        </material>
      </visual>
      <collision>
        <origin rpy="0 0 0" xyz="0 0 0"/>
        <geometry>
          <mesh filename="package://mara_description/meshes/H-ROS_Robot_mara2.stl" scale="0.001 0.001 0.001"/>
        </geometry>
      </collision>
    </link>
    <gazebo reference="${prefix}motor3_link">
      <material>Gazebo/White</material>
      <selfCollide>False</selfCollide>
    </gazebo>

    <link name="${prefix}motor4_link">
      <inertial>
        <origin rpy="0 0 0" xyz="8.625E-08 -4.6583E-06 0.03145"/>
        <mass value="1.1"/>
        <inertia ixx="0.01464" ixy="0.0" ixz="0.0" iyy="0.00895" iyz="-0.00631" izz="0.00725"/>
      </inertial>
      <visual>
        <origin rpy="0 0 0" xyz="0 0 0"/>
        <geometry>
          <mesh filename="package://mara_description/meshes/H-ROS_Robot_LINK2.stl" scale="0.001 0.001 0.001"/>
        </geometry>
        <material name="Gazebo/Black">
          <color rgba="0. 0. 0. 1"/>
        </material>
      </visual>
      <collision>
        <origin rpy="0 0 0" xyz="0 0 0"/>
        <geometry>
          <mesh filename="package://mara_description/meshes/H-ROS_Robot_LINK2.stl" scale="0.001 0.001 0.001"/>
        </geometry>
      </collision>
    </link>
    <gazebo reference="${prefix}motor4_link">
      <material>Gazebo/Black</material>
      <selfCollide>False</selfCollide>
    </gazebo>

    <link name="${prefix}motor5_link">
      <inertial>
        <origin rpy="0 0 0" xyz="8.625E-08 -4.6583E-06 0.03145"/>
        <mass value="2.9"/>
        <inertia ixx="0.03406" ixy="0.0" ixz="0.0" iyy="0.01066" iyz="0.00989" izz="0.02563"/>
      </inertial>
      <visual>
        <origin rpy="0 0 0" xyz="0 0 0"/>
        <geometry>
          <mesh filename="package://mara_description/meshes/H-ROS_Robot_mara3.stl" scale="0.001 0.001 0.001"/>
        </geometry>
        <material name="Gazebo/White">
          <color rgba="0. 0. 0. 1"/>
        </material>
      </visual>
      <collision>
        <origin rpy="0 0 0" xyz="0 0 0"/>
        <geometry>
          <mesh filename="package://mara_description/meshes/H-ROS_Robot_mara3.stl" scale="0.001 0.001 0.001"/>
        </geometry>
      </collision>
    </link>
    <gazebo reference="${prefix}motor5_link">
      <material>Gazebo/White</material>
      <selfCollide>False</selfCollide>
    </gazebo>

    <link name="${prefix}motor6_link">
      <inertial>
        <origin rpy="0 0 0" xyz="8.625E-08 -4.6583E-06 0.03145"/>
        <mass value="2.9"/>
        <inertia ixx="0.0005" ixy="0.0" ixz="0.0" iyy="0.0005" iyz="0.0000" izz="0.0003"/>
      </inertial>
      <visual>
        <origin rpy="0 0 0" xyz="0 0 0"/>
        <geometry>
          <mesh filename="package://mara_description/meshes/gripper_support.stl" scale="0.001 0.001 0.001"/>
        </geometry>
        <material name="Gazebo/Black">
          <color rgba="0. 0. 0. 1"/>
        </material>
      </visual>
      <collision>
        <origin rpy="0 0 0" xyz="0 0 0"/>
        <geometry>
          <mesh filename="package://mara_description/meshes/gripper_support.stl" scale="0.001 0.001 0.001"/>
        </geometry>
      </collision>
    </link>
    <gazebo reference="${prefix}motor6_link">
      <material>Gazebo/Black</material>
      <selfCollide>False</selfCollide>
    </gazebo>

    <link name="${prefix}ee_link">
      <visual>
        <geometry>
          <box size="0.01 0.01 0.01"/>
        </geometry>
        <material name="Gazebo/Grey">
          <color rgba="0. 0. 0. 1"/>
        </material>
      </visual>
      <collision>
        <geometry>
        <box size="0.01 0.01 0.01"/>
        </geometry>
      </collision>
    </link>
    <gazebo reference="${prefix}ee_link">
      <material>Gazebo/Blue</material>
      <selfCollide>False</selfCollide>
    </gazebo>

    <joint name="${prefix}motor1" type="revolute">
      <origin rpy="0 0 0" xyz="0 0 0.00625"/>
      <parent link="${prefix}base_link"/>
      <child link="${prefix}motor1_link"/>
      <axis xyz="0 0 -1"/>
      <limit effort="330.0" lower="-3.1416" upper="3.1416" velocity="2.16"/>
      <dynamics damping="0" friction="0"/>
    </joint>

    <joint name="${prefix}motor2" type="revolute">
      <origin rpy="0 0 0" xyz="0 -0.100499999 0.1545"/>
      <parent link="${prefix}motor1_link"/>
      <child link="${prefix}motor2_link"/>
      <axis xyz="0 -1 0"/>
      <limit effort="330.0" lower="-3.1416" upper="3.1416" velocity="2.16"/>
      <dynamics damping="0" friction="0"/>
    </joint>

    <joint name="${prefix}motor3" type="revolute">
      <origin rpy="0 0 0" xyz="0 -0.000499999 0.2"/>
      <parent link="${prefix}motor2_link"/>
      <child link="${prefix}motor3_link"/>
      <axis xyz="0 1 0"/>
      <limit effort="150" lower="-3.1416" upper="3.1416" velocity="3.15"/>
      <dynamics damping="0" friction="0"/>
    </joint>

    <joint name="${prefix}motor4" type="revolute">
      <origin rpy="0 0 0" xyz="0 0.09999 0.12999997"/>
      <parent link="${prefix}motor3_link"/>
      <child link="${prefix}motor4_link"/>
      <axis xyz="0 0 -1"/>
      <limit effort="54" lower="-3.1416" upper="3.1416" velocity="3.2"/>
      <dynamics damping="0" friction="0"/>
    </joint>

    <joint name="${prefix}motor5" type="revolute">
      <origin rpy="0 0 0" xyz="0 -0.096999 0.15906"/>
      <parent link="${prefix}motor4_link"/>
      <child link="${prefix}motor5_link"/>
      <axis xyz="0 1 0"/>
      <limit effort="54" lower="-3.1416" upper="3.1416" velocity="3.2"/>
      <dynamics damping="0" friction="0"/>
    </joint>

    <joint name="${prefix}motor6" type="revolute">
      <origin rpy="0 0 0" xyz="0 0.097 0.12"/>
      <parent link="${prefix}motor5_link"/>
      <child link="${prefix}motor6_link"/>
      <axis xyz="0 0 1"/>
      <limit effort="54" lower="-3.1416" upper="3.1416" velocity="3.2"/>
      <dynamics damping="0" friction="0"/>
    </joint>

    <joint name="${prefix}ee_link" type="fixed">
      <origin rpy="0 -1.57 0" xyz="0 0.0 0.21"/>
      <parent link="${prefix}motor6_link"/>
      <child link="${prefix}ee_link"/>
    </joint>


    <xacro:mara_transmission prefix="${prefix}" />
    <xacro:mara_gazebo prefix="${prefix}" />

    <!-- ROS ${prefix}base_link to UR 'Base' Coordinates transform -->
    <link name="${prefix}base"/>
    <joint name="${prefix}${prefix}base_link-base_fixed_joint" type="fixed">
      <!-- NOTE: this rotation is only needed as long as ${prefix}base_link itself is
                 not corrected wrt the real robot (ie: rotated over 180
                 degrees)
      -->
      <origin xyz="0 0 0" rpy="0 0 ${-pi}"/>
      <parent link="${prefix}${prefix}base_link"/>
      <child link="${prefix}base"/>
    </joint>

    <!-- Frame coincident with all-zeros TCP on UR controller -->
    <link name="${prefix}tool0"/>
    <joint name="${prefix}${prefix}motor6_link-tool0_fixed_joint" type="fixed">
      <origin xyz="0 0 0" rpy="${pi/-2.0} 0 0"/>
      <parent link="${prefix}${prefix}motor6_link"/>
      <child link="${prefix}tool0"/>
    </joint>

  </xacro:macro>
</robot>
