<?xml version="1.0" ?>
<!-- =================================================================================== -->
<!-- |    This document was autogenerated by xacro from scara_e1_model_3joints.urdf.xacro | -->
<!-- |    EDITING THIS FILE BY HAND IS NOT RECOMMENDED                                 | -->
<!-- =================================================================================== -->
<robot name="mara_3joints" xmlns:xacro="http://ros.org/wiki/xacro">
  <link name="world">
  </link>

  <link name="mara_base_link">
    <inertial>
      <origin rpy="0 0 0" xyz="8.625E-08 -4.6583E-06 0.03145"/>
      <mass value="7.033"/>
      <inertia ixx="0.1478344" ixy="-0.00001" ixz="0.0" iyy="0.14782335" iyz="0.0" izz="0.29471799"/>
    </inertial>
    <visual>
      <origin rpy="0 0 0" xyz="0 0 0"/>
      <geometry>
        <mesh filename="package://mara_description/meshes/H-ROS_Robot_BASE.stl" scale="0.001 0.001 0.001"/>
      </geometry>
      <material name="Gazebo/Grey">
        <color rgba="0. 0. 0. 1"/>
      </material>
    </visual>
    <collision>
      <origin rpy="0 0 0" xyz="0 0 0"/>
      <geometry>
        <mesh filename="package://mara_description/meshes/H-ROS_Robot_BASE.stl" scale="0.001 0.001 0.001"/>
      </geometry>
    </collision>
  </link>
  <gazebo reference="mara_base_link">
    <material>Gazebo/Grey</material>
    <selfCollide>False</selfCollide>
  </gazebo>

  <link name="motor1_link">
    <inertial>
      <origin rpy="0 0 0" xyz="8.625E-08 -4.6583E-06 0.03145"/>
      <mass value="5.8"/>
      <inertia ixx="0.10105893" ixy="0.000211" ixz="-0.004" iyy="0.09386624" iyz="-0.01698537" izz="0.01449937"/>
    </inertial>
    <visual>
      <origin rpy="0 0 0" xyz="0 0 0"/>
      <geometry>
        <mesh filename="package://mara_description/meshes/H-ROS_Robot_mara1.stl" scale="0.001 0.001 0.001"/>
      </geometry>
      <material name="Gazebo/Grey">
        <color rgba="0. 0. 0. 1"/>
      </material>
    </visual>
    <collision>
      <origin rpy="0 0 0" xyz="0 0 0"/>
      <geometry>
        <mesh filename="package://mara_description/meshes/H-ROS_Robot_mara1.stl" scale="0.001 0.001 0.001"/>
      </geometry>
    </collision>
  </link>
  <gazebo reference="motor1_link">
    <material>Gazebo/Grey</material>
    <selfCollide>False</selfCollide>
  </gazebo>

  <link name="motor2_link">
    <inertial>
      <origin rpy="0 0 0" xyz="8.625E-08 -4.6583E-06 0.03145"/>
      <mass value="1.03237"/>
      <inertia ixx="0.014865226" ixy="0.0" ixz="0.0" iyy="0.01557" iyz="0.00071" izz="0.00092"/>
    </inertial>
    <visual>
      <origin rpy="0 0 0" xyz="0 0 0"/>
      <geometry>
        <mesh filename="package://mara_description/meshes/H-ROS_Robot_LINK1.stl" scale="0.001 0.001 0.001"/>
      </geometry>
      <material name="Gazebo/Black">
        <color rgba="0. 0. 0. 1"/>
      </material>
    </visual>
    <collision>
      <origin rpy="0 0 0" xyz="0 0 0"/>
      <geometry>
        <mesh filename="package://mara_description/meshes/H-ROS_Robot_LINK1.stl" scale="0.001 0.001 0.001"/>
      </geometry>
    </collision>
  </link>
  <gazebo reference="motor2_link">
    <material>Gazebo/Black</material>
    <selfCollide>False</selfCollide>
  </gazebo>

  <link name="motor3_link">
    <inertial>
      <origin rpy="0 0 0" xyz="8.625E-08 -4.6583E-06 0.03145"/>
      <mass value="3.8"/>
      <inertia ixx="0.04517" ixy="0.00002" ixz="0.0" iyy="0.01587" iyz="0.01444" izz="0.03303"/>
    </inertial>
    <visual>
      <origin rpy="0 0 0" xyz="0 0 0"/>
      <geometry>
        <mesh filename="package://mara_description/meshes/H-ROS_Robot_mara2.stl" scale="0.001 0.001 0.001"/>
      </geometry>
      <material name="Gazebo/Grey">
        <color rgba="0. 0. 0. 1"/>
      </material>
    </visual>
    <collision>
      <origin rpy="0 0 0" xyz="0 0 0"/>
      <geometry>
        <mesh filename="package://mara_description/meshes/H-ROS_Robot_mara2.stl" scale="0.001 0.001 0.001"/>
      </geometry>
    </collision>
  </link>
  <gazebo reference="motor3_link">
    <material>Gazebo/Grey</material>
    <selfCollide>False</selfCollide>
  </gazebo>

  <link name="motor4_link">
    <inertial>
      <origin rpy="0 0 0" xyz="8.625E-08 -4.6583E-06 0.03145"/>
      <mass value="1.1"/>
      <inertia ixx="0.01464" ixy="0.0" ixz="0.0" iyy="0.00895" iyz="-0.00631" izz="0.00725"/>
    </inertial>
    <visual>
      <origin rpy="0 0 0" xyz="0 0 0"/>
      <geometry>
        <mesh filename="package://mara_description/meshes/H-ROS_Robot_LINK2.stl" scale="0.001 0.001 0.001"/>
      </geometry>
      <material name="Gazebo/Black">
        <color rgba="0. 0. 0. 1"/>
      </material>
    </visual>
    <collision>
      <origin rpy="0 0 0" xyz="0 0 0"/>
      <geometry>
        <mesh filename="package://mara_description/meshes/H-ROS_Robot_LINK2.stl" scale="0.001 0.001 0.001"/>
      </geometry>
    </collision>
  </link>
  <gazebo reference="motor4_link">
    <material>Gazebo/Black</material>
    <selfCollide>False</selfCollide>
  </gazebo>

  <link name="motor5_link">
    <inertial>
      <origin rpy="0 0 0" xyz="8.625E-08 -4.6583E-06 0.03145"/>
      <mass value="2.9"/>
      <inertia ixx="0.03406" ixy="0.0" ixz="0.0" iyy="0.01066" iyz="0.00989" izz="0.02563"/>
    </inertial>
    <visual>
      <origin rpy="0 0 0" xyz="0 0 0"/>
      <geometry>
        <mesh filename="package://mara_description/meshes/H-ROS_Robot_mara3.stl" scale="0.001 0.001 0.001"/>
      </geometry>
      <material name="Gazebo/Grey">
        <color rgba="0. 0. 0. 1"/>
      </material>
    </visual>
    <collision>
      <origin rpy="0 0 0" xyz="0 0 0"/>
      <geometry>
        <mesh filename="package://mara_description/meshes/H-ROS_Robot_mara3.stl" scale="0.001 0.001 0.001"/>
      </geometry>
    </collision>
  </link>
  <gazebo reference="motor5_link">
    <material>Gazebo/Grey</material>
    <selfCollide>False</selfCollide>
  </gazebo>

  <link name="motor6_link">
    <inertial>
      <origin rpy="0 0 0" xyz="8.625E-08 -4.6583E-06 0.03145"/>
      <mass value="2.9"/>
      <inertia ixx="0.0005" ixy="0.0" ixz="0.0" iyy="0.0005" iyz="0.0000" izz="0.0003"/>
    </inertial>
    <visual>
      <origin rpy="0 0 0" xyz="0 0 0"/>
      <geometry>
        <mesh filename="package://mara_description/meshes/gripper_support.stl" scale="0.001 0.001 0.001"/>
      </geometry>
      <material name="Gazebo/Black">
        <color rgba="0. 0. 0. 1"/>
      </material>
    </visual>
    <collision>
      <origin rpy="0 0 0" xyz="0 0 0"/>
      <geometry>
        <mesh filename="package://mara_description/meshes/gripper_support.stl" scale="0.001 0.001 0.001"/>
      </geometry>
    </collision>
  </link>
  <gazebo reference="motor6_link">
    <material>Gazebo/Black</material>
    <selfCollide>False</selfCollide>
  </gazebo>


  <link name="robotiq_arg2f_base_link">
    <inertial>
      <origin xyz="8.625E-08 -4.6583E-06 0.03145" rpy="0 0 0" />
      <mass value="0.22652" />
      <inertia ixx="0.00020005" ixy="-4.2442E-10" ixz="-2.9069E-10" iyy="0.00017832" iyz="-3.4402E-08" izz="0.00013478" />
    </inertial>
    <visual>
      <origin xyz="0 0 0" rpy="0 0 0" />
      <geometry>
        <mesh filename="package://robotiq_arg2f_model_visualization/meshes/GRIPPER_base_axis.stl" scale="0.001 0.001 0.001"/>
      </geometry>
      <material name="">
        <color rgba="0.1 0.1 0.1 1" />
      </material>
    </visual>
    <collision>
      <origin xyz="0 0 0" rpy="0 0 0" />
      <geometry>
        <mesh filename="package://robotiq_arg2f_model_visualization/meshes/GRIPPER_base_axis.stl" scale="0.001 0.001 0.001"/>
      </geometry>
    </collision>
  </link>
  <gazebo reference="robotiq_arg2f_base_link">
    <material>Gazebo/Grey</material>
    <selfCollide>False</selfCollide>
  </gazebo>

  <link name="left_outer_knuckle">
    <inertial>
      <origin xyz="-0.000200000000003065 0.0199435877845359 0.0292245259211331" rpy="0 0 0" />
      <mass value="0.00853198276973456" />
      <inertia
          ixx="2.89328108496468E-06"
          ixy="-1.57935047237397E-19"
          ixz="-1.93980378593255E-19"
          iyy="1.86719750325683E-06"
          iyz="-1.21858577871576E-06"
          izz="1.21905238907251E-06" />
    </inertial>
    <visual>
      <origin xyz="0 0 0" rpy="0 0 0" />
      <geometry>
        <mesh filename="package://robotiq_arg2f_model_visualization/meshes/robotiq_arg2f_140_outer_knuckle.stl" />
      </geometry>
      <material name="">
        <color rgba="0.792156862745098 0.819607843137255 0.933333333333333 1" />
      </material>
    </visual>
    <collision>
      <origin xyz="0 0 0" rpy="0 0 0" />
      <geometry>
        <mesh filename="package://robotiq_arg2f_model_visualization/meshes/robotiq_arg2f_140_outer_knuckle.stl" />
      </geometry>
    </collision>
  </link>
  <gazebo reference="left_outer_knuckle">
    <material>Gazebo/Grey</material>
    <selfCollide>False</selfCollide>
  </gazebo>

  <link name="right_outer_knuckle">
    <inertial>
      <origin xyz="-0.000200000000003065 0.0199435877845359 0.0292245259211331" rpy="0 0 0" />
      <mass value="0.00853198276973456" />
      <inertia
          ixx="2.89328108496468E-06"
          ixy="-1.57935047237397E-19"
          ixz="-1.93980378593255E-19"
          iyy="1.86719750325683E-06"
          iyz="-1.21858577871576E-06"
          izz="1.21905238907251E-06" />
    </inertial>
    <visual>
      <origin xyz="0 0 0" rpy="0 0 0" />
      <geometry>
        <mesh filename="package://robotiq_arg2f_model_visualization/meshes/robotiq_arg2f_140_outer_knuckle.stl" />
      </geometry>
      <material name="">
        <color rgba="0.792156862745098 0.819607843137255 0.933333333333333 1" />
      </material>
    </visual>
    <collision>
      <origin xyz="0 0 0" rpy="0 0 0" />
      <geometry>
        <mesh filename="package://robotiq_arg2f_model_visualization/meshes/robotiq_arg2f_140_outer_knuckle.stl" />
      </geometry>
    </collision>
  </link>
  <gazebo reference="right_outer_knuckle">
    <material>Gazebo/Grey</material>
    <selfCollide>False</selfCollide>
  </gazebo>

  <link name="left_inner_knuckle">
    <inertial>
      <origin xyz="0.000123011831763771 0.0507850843201817 0.00103968640075166" rpy="0 0 0" />
      <mass value="0.0271177346495152" />
      <inertia
          ixx="2.61910379223783E-05"
          ixy="-2.43616858946494E-07"
          ixz="-6.37789906117123E-09"
          iyy="2.8270243746167E-06"
          iyz="-5.37200748039765E-07"
          izz="2.83695868220296E-05" />
    </inertial>
    <visual>
      <origin xyz="0 0 0" rpy="0 0 0" />
      <geometry>
        <mesh filename="package://robotiq_arg2f_model_visualization/meshes/robotiq_arg2f_140_inner_knuckle.stl" />
      </geometry>
      <material name="">
        <color rgba="0.1 0.1 0.1 1" />
      </material>
    </visual>
    <collision>
      <origin xyz="0 0 0" rpy="0 0 0" />
      <geometry>
        <mesh filename="package://robotiq_arg2f_model_visualization/meshes/robotiq_arg2f_140_inner_knuckle.stl" />
      </geometry>
    </collision>
  </link>
  <gazebo reference="left_inner_knuckle">
    <material>Gazebo/Grey</material>
    <selfCollide>False</selfCollide>
  </gazebo>

  <link name="right_inner_knuckle">
    <inertial>
      <origin xyz="0.000123011831763771 0.0507850843201817 0.00103968640075166" rpy="0 0 0" />
      <mass value="0.0271177346495152" />
      <inertia
          ixx="2.61910379223783E-05"
          ixy="-2.43616858946494E-07"
          ixz="-6.37789906117123E-09"
          iyy="2.8270243746167E-06"
          iyz="-5.37200748039765E-07"
          izz="2.83695868220296E-05" />
    </inertial>
    <visual>
      <origin xyz="0 0 0" rpy="0 0 0" />
      <geometry>
        <mesh filename="package://robotiq_arg2f_model_visualization/meshes/robotiq_arg2f_140_inner_knuckle.stl" />
      </geometry>
      <material name="">
        <color rgba="0.1 0.1 0.1 1" />
      </material>
    </visual>
    <collision>
      <origin xyz="0 0 0" rpy="0 0 0" />
      <geometry>
        <mesh filename="package://robotiq_arg2f_model_visualization/meshes/robotiq_arg2f_140_inner_knuckle.stl" />
      </geometry>
    </collision>
  </link>
  <gazebo reference="right_inner_knuckle">
    <material>Gazebo/Grey</material>
    <selfCollide>False</selfCollide>
  </gazebo>

  <link name="left_inner_finger">
    <inertial>
      <origin xyz="0.000299999999999317 0.0160078233491243 -0.0136945669206257" rpy="0 0 0" />
      <mass value="0.0104003125914103" />
      <inertia
          ixx="2.71909453810972E-06"
          ixy="1.35402465472579E-21"
          ixz="-7.1817349065269E-22"
          iyy="7.69100314106116E-07"
          iyz="6.74715432769696E-07"
          izz="2.30315190420171E-06" />
    </inertial>
    <visual>
      <origin xyz="0 0 0" rpy="0 0 0" />
      <geometry>
        <mesh filename="package://robotiq_arg2f_model_visualization/meshes/robotiq_arg2f_140_inner_finger.stl" />
      </geometry>
      <material name="">
        <color rgba="0.1 0.1 0.1 1" />
      </material>
    </visual>
    <collision>
      <origin xyz="0 0 0" rpy="0 0 0" />
      <geometry>
        <mesh filename="package://robotiq_arg2f_model_visualization/meshes/robotiq_arg2f_140_inner_finger.stl" />
      </geometry>
    </collision>
  </link>
  <gazebo reference="left_inner_finger">
    <material>Gazebo/Grey</material>
    <selfCollide>False</selfCollide>
  </gazebo>

  <link name="right_inner_finger">
    <inertial>
      <origin xyz="0.000299999999999317 0.0160078233491243 -0.0136945669206257" rpy="0 0 0" />
      <mass value="0.0104003125914103" />
      <inertia
          ixx="2.71909453810972E-06"
          ixy="1.35402465472579E-21"
          ixz="-7.1817349065269E-22"
          iyy="7.69100314106116E-07"
          iyz="6.74715432769696E-07"
          izz="2.30315190420171E-06" />
    </inertial>
    <visual>
      <origin xyz="0 0 0" rpy="0 0 0" />
      <geometry>
        <mesh filename="package://robotiq_arg2f_model_visualization/meshes/robotiq_arg2f_140_inner_finger.stl" />
      </geometry>
      <material name="">
        <color rgba="0.1 0.1 0.1 1" />
      </material>
    </visual>
    <collision>
      <origin xyz="0 0 0" rpy="0 0 0" />
      <geometry>
        <mesh filename="package://robotiq_arg2f_model_visualization/meshes/robotiq_arg2f_140_inner_finger.stl" />
      </geometry>
    </collision>
  </link>
  <gazebo reference="right_inner_finger">
    <material>Gazebo/Grey</material>
    <selfCollide>False</selfCollide>
  </gazebo>

  <link name="left_outer_finger">
    <inertial>
      <origin xyz="0.00030115855001899 0.0373907951953854 -0.0208027427000385" rpy="0 0 0" />
      <mass value="0.022614240507152" />
      <inertia
          ixx="1.52518312458174E-05"
          ixy="9.76583423954399E-10"
          ixz="-5.43838577022588E-10"
          iyy="6.17694243867776E-06"
          iyz="6.78636130740228E-06"
          izz="1.16494917907219E-05" />
    </inertial>
    <visual>
      <origin xyz="0 0 0" rpy="0 0 0" />
      <geometry>
        <mesh filename="package://robotiq_arg2f_model_visualization/meshes/robotiq_arg2f_140_outer_finger.stl" />
      </geometry>
      <material name="">
        <color rgba="0.1 0.1 0.1 1" />
      </material>
    </visual>
    <collision>
      <origin xyz="0 0 0" rpy="0 0 0" />
      <geometry>
        <mesh filename="package://robotiq_arg2f_model_visualization/meshes/robotiq_arg2f_140_outer_finger.stl" />
      </geometry>
    </collision>
  </link>
  <gazebo reference="left_outer_finger">
    <material>Gazebo/Grey</material>
    <selfCollide>False</selfCollide>
  </gazebo>

  <link name="right_outer_finger">
    <inertial>
      <origin xyz="0.00030115855001899 0.0373907951953854 -0.0208027427000385" rpy="0 0 0" />
      <mass value="0.022614240507152" />
      <inertia
          ixx="1.52518312458174E-05"
          ixy="9.76583423954399E-10"
          ixz="-5.43838577022588E-10"
          iyy="6.17694243867776E-06"
          iyz="6.78636130740228E-06"
          izz="1.16494917907219E-05" />
    </inertial>
    <visual>
      <origin xyz="0 0 0" rpy="0 0 0" />
      <geometry>
        <mesh filename="package://robotiq_arg2f_model_visualization/meshes/robotiq_arg2f_140_outer_finger.stl" />
      </geometry>
      <material name="">
        <color rgba="0.1 0.1 0.1 1" />
      </material>
    </visual>
    <collision>
      <origin xyz="0 0 0" rpy="0 0 0" />
      <geometry>
        <mesh filename="package://robotiq_arg2f_model_visualization/meshes/robotiq_arg2f_140_outer_finger.stl" />
      </geometry>
    </collision>
  </link>
  <gazebo reference="right_outer_finger">
    <material>Gazebo/Grey</material>
    <selfCollide>False</selfCollide>
  </gazebo>

  <link name="ee_link">
  </link>

  <joint name="world_to_base_joint" type="fixed">
    <origin rpy="0 0 0" xyz="0 0 0.02"/>
    <parent link="world"/>
    <child link="mara_base_link"/>
  </joint>

  <joint name="motor1" type="revolute">
    <origin rpy="0 0 0" xyz="0 0 0.00625"/>
    <parent link="mara_base_link"/>
    <child link="motor1_link"/>
    <axis xyz="0 0 1"/>
    <limit effort="330.0" lower="-6.28318530718" upper="6.28318530718" velocity="2.16"/>
    <dynamics damping="0" friction="0"/>
  </joint>

  <joint name="motor2" type="revolute">
    <origin rpy="0 0 0" xyz="0 -0.100499999 0.1545"/>
    <parent link="motor1_link"/>
    <child link="motor2_link"/>
    <axis xyz="0 1 0"/>
    <limit effort="330.0" lower="-6.28318530718" upper="6.28318530718" velocity="2.16"/>
    <dynamics damping="0" friction="0"/>
  </joint>

  <joint name="motor3" type="revolute">
    <origin rpy="0 0 0" xyz="0 -0.000499999 0.2"/>
    <parent link="motor2_link"/>
    <child link="motor3_link"/>
    <axis xyz="0 1 0"/>
    <limit effort="150" lower="-6.28318530718" upper="6.28318530718" velocity="3.15"/>
    <dynamics damping="0" friction="0"/>
  </joint>

  <joint name="motor4" type="revolute">
    <origin rpy="0 0 0" xyz="0 0.09999 0.12999997"/>
    <parent link="motor3_link"/>
    <child link="motor4_link"/>
    <axis xyz="0 0 1"/>
    <limit effort="54" lower="-6.28318530718" upper="6.28318530718" velocity="3.2"/>
    <dynamics damping="0" friction="0"/>
  </joint>

  <joint name="motor5" type="revolute">
    <origin rpy="0 0 0" xyz="0 -0.096999 0.15906"/>
    <parent link="motor4_link"/>
    <child link="motor5_link"/>
    <axis xyz="0 1 0"/>
    <limit effort="54" lower="-6.28318530718" upper="6.28318530718" velocity="3.2"/>
    <dynamics damping="0" friction="0"/>
  </joint>

  <joint name="motor6" type="revolute">
    <origin rpy="0 0 0" xyz="0 0.00 0.0"/>
    <parent link="motor5_link"/>
    <child link="motor6_link"/>
    <axis xyz="0 0 1"/>
    <limit effort="54" lower="-6.28318530718" upper="6.28318530718" velocity="3.2"/>
    <dynamics damping="0" friction="0"/>
  </joint>

  <joint name="ee_link_joint" type="fixed">
    <origin rpy="0 0 0" xyz="0 0.097 0.33 "/>
    <parent link="motor6_link"/>
    <child link="ee_link"/>
  </joint>

  <joint name="end_effector_adapter_to_robotiq" type="fixed">
    <origin rpy="0 0 1.57" xyz=" 0 0 0.065"/>
    <parent link="motor6_link"/>
    <child link="robotiq_arg2f_base_link"/>
  </joint>
  <joint name="left_outer_knuckle_joint" type="revolute">
    <origin xyz="0.030601 0 0.050905" rpy="2.29579632679 0 1.57" />
    <parent link="robotiq_arg2f_base_link" />
    <child link="left_outer_knuckle" />
    <axis xyz="-1 0 0" />
    <limit lower="0" upper="6.28318530718" velocity="0.0" effort="0" />
  </joint>

  <joint name="right_outer_knuckle_joint" type="revolute">
    <origin xyz="-0.030601 0 0.050905" rpy="2.29579632679 0 4.71" />
    <parent link="robotiq_arg2f_base_link" />
    <child link="right_outer_knuckle" />
    <axis xyz="-1 0 0" />
    <limit lower="0" upper="6.28318530718" velocity="0.0" effort="0" />
  </joint>

  <joint name="left_inner_knuckle_joint" type="revolute">
    <origin xyz="0.0127 0 0.05642" rpy="2.29579632679 0 1.57" />
    <parent link="robotiq_arg2f_base_link" />
    <child link="left_inner_knuckle" />
    <axis xyz="-1 0 0" />
    <limit lower="0" upper="0.7" velocity="0.1" effort="100" />
  </joint>

  <joint name="right_inner_knuckle_joint" type="revolute">
    <origin xyz="-0.0127 0 0.05642" rpy="2.29579632679 0 4.71" />
    <parent link="robotiq_arg2f_base_link" />
    <child link="right_inner_knuckle" />
    <axis xyz="-1 0 0" />
    <limit lower="0" upper="0.7" velocity="0.1" effort="100" />
  </joint>

  <joint name="left_outer_finger_joint" type="revolute">
    <origin xyz="0 0.01821998610742 0.0260018192872234" rpy="0 0 0" />
    <parent link="left_outer_knuckle" />
    <child link="left_outer_finger" />
    <axis xyz="-1 0 0" />
    <limit lower="-6.28318530718" upper="6.28318530718" velocity="2.0" effort="1000" />
  </joint>

  <joint name="right_outer_finger_joint" type="revolute">
    <origin xyz="0 0.01821998610742 0.0260018192872234" rpy="0 0 0" />
    <parent link="right_outer_knuckle" />
    <child link="right_outer_finger" />
    <axis xyz="-1 0 0" />
    <limit lower="-6.28318530718" upper="6.28318530718" velocity="2.0" effort="1000" />
  </joint>

  <joint name="left_inner_finger_joint" type="revolute">
    <origin xyz="0 0.0817554015893473 -0.0282203446692936" rpy="-.725 0 0" />
    <parent link="left_outer_finger" />
    <child link="left_inner_finger" />
    <axis xyz="-1 0 0" />
    <limit lower="-6.28318530718" upper="6.28318530718" velocity="2.0" effort="1000" />
  </joint>

  <joint name="right_inner_finger_joint" type="revolute">
    <origin xyz="0 0.0817554015893473 -0.0282203446692936" rpy="-.725 0 0" />
    <parent link="right_outer_finger" />
    <child link="right_inner_finger" />
    <axis xyz="-1 0 0" />
    <limit lower="-6.28318530718" upper="6.28318530718" velocity="2.0" effort="1000" />
  </joint>

  <gazebo>
    <joint name="left_inner_finger_knuckle_joint" type="revolute">
      <pose frame="">0 0.006 -0.018 0 0 0</pose>
      <parent>robot::left_inner_knuckle</parent>
      <child>robot::left_inner_finger</child>
      <axis>
        <xyz>0 0 -1</xyz>
        <limit>
          <lower>-0.6</lower>
          <upper>0.6</upper>
          <velocity>0</velocity>
          <effort>0</effort>
        </limit>
      </axis>
    </joint>

    <joint name="right_inner_finger_knuckle_joint" type="revolute">
      <pose frame="">0 0.006 -0.018 0 0 0</pose>
      <parent>robot::right_inner_knuckle</parent>
      <child>robot::right_inner_finger</child>
      <axis>
        <xyz>0 0 -1</xyz>
        <limit>
          <lower>-0.6</lower>
          <upper>0.6</upper>
          <velocity>0</velocity>
          <effort>0</effort>
        </limit>
      </axis>
    </joint>

    <plugin filename="libRobotiq140Plugin.so" name="robotiq_arg2f_gazebo_plugins"/>
    <plugin filename="libgazebo_grasp_fix.so" name="gazebo_grasp_fix">
      <arm>
        <arm_name>robot</arm_name>
        <palm_link>left_inner_finger</palm_link>
        <gripper_link>left_inner_finger</gripper_link>
        <gripper_link>right_inner_finger</gripper_link>
        <gripper_link>left_inner_knuckle</gripper_link>
        <gripper_link>right_inner_knuckle</gripper_link>
      </arm>
      <forces_angle_tolerance>100</forces_angle_tolerance>
      <update_rate>4</update_rate>
      <grip_count_threshold>4</grip_count_threshold>
      <max_grip_count>8</max_grip_count>
      <release_tolerance>0.5</release_tolerance>
      <disable_collisions_on_attach>false</disable_collisions_on_attach>
      <contact_topic>__default_topic__</contact_topic>
   </plugin>
  </gazebo>

  <transmission name="motor1_trans">
    <type>transmission_interface/SimpleTransmission</type>
    <joint name="motor1">
      <hardwareInterface>hardware_interface/PositionJointInterface</hardwareInterface>
    </joint>
    <actuator name="motor1">
      <mechanicalReduction>1</mechanicalReduction>
    </actuator>
  </transmission>
  <transmission name="motor2_trans">
    <type>transmission_interface/SimpleTransmission</type>
    <joint name="motor2">
      <hardwareInterface>hardware_interface/PositionJointInterface</hardwareInterface>
    </joint>
    <actuator name="motor2">
      <mechanicalReduction>1</mechanicalReduction>
    </actuator>
  </transmission>
  <transmission name="motor3_trans">
    <type>transmission_interface/SimpleTransmission</type>
    <joint name="motor3">
      <hardwareInterface>hardware_interface/PositionJointInterface</hardwareInterface>
    </joint>
    <actuator name="motor3">
      <mechanicalReduction>1</mechanicalReduction>
    </actuator>
  </transmission>
  <transmission name="motor4_trans">
    <type>transmission_interface/SimpleTransmission</type>
    <joint name="motor4">
      <hardwareInterface>hardware_interface/PositionJointInterface</hardwareInterface>
    </joint>
    <actuator name="motor4">
      <mechanicalReduction>1</mechanicalReduction>
    </actuator>
  </transmission>
  <transmission name="motor5_trans">
    <type>transmission_interface/SimpleTransmission</type>
    <joint name="motor5">
      <hardwareInterface>hardware_interface/PositionJointInterface</hardwareInterface>
    </joint>
    <actuator name="motor5">
      <mechanicalReduction>1</mechanicalReduction>
    </actuator>
  </transmission>
  <transmission name="motor6_trans">
    <type>transmission_interface/SimpleTransmission</type>
    <joint name="motor6">
      <hardwareInterface>hardware_interface/PositionJointInterface</hardwareInterface>
    </joint>
    <actuator name="motor6">
      <mechanicalReduction>1</mechanicalReduction>
    </actuator>
  </transmission>

  <gazebo>
<!--
    <plugin name="joint_state_publisher" filename="libgazebo_ros_joint_state_publisher.so">
  		<robotNamespace>/robot</robotNamespace>
  		<jointName>motor1, motor2, motor3, motor4, motor5, motor6, right_inner_finger_knuckle_joint, left_inner_finger_knuckle_joint,right_inner_finger_joint,left_inner_finger_joint,right_outer_finger_joint,left_outer_finger_joint,right_inner_knuckle_joint,left_inner_knuckle_joint</jointName>
  		<updateRate>100</updateRate>
  		<alwaysOn>true</alwaysOn>
  	</plugin>
-->
    <plugin filename="libgazebo_ros_control.so" name="gazebo_ros_control">
      <!-- <robotNamespace>/</robotNamespace>
      <robotSimType>gazebo_ros_control/DefaultRobotHWSim</robotSimType> -->
    </plugin>
  </gazebo>

</robot>
