<?xml version="1.0" ?>
<!-- =================================================================================== -->
<!-- |    This document was autogenerated by xacro from mara_robot_camera_top.urdf.xacro | -->
<!-- |    EDITING THIS FILE BY HAND IS NOT RECOMMENDED                                 | -->
<!-- =================================================================================== -->
<robot name="mara" xmlns:xacro="http://ros.org/wiki/xacro">
  <gazebo>
    <plugin filename="libgazebo_ros_control.so" name="ros_control">
      <!--robotNamespace>/</robotNamespace-->
      <!--robotSimType>gazebo_ros_control/DefaultRobotHWSim</robotSimType-->
    </plugin>
    <!--
    <plugin name="gazebo_ros_power_monitor_controller" filename="libgazebo_ros_power_monitor.so">
      <alwaysOn>true</alwaysOn>
      <updateRate>1.0</updateRate>
      <timeout>5</timeout>
      <powerStateTopic>power_state</powerStateTopic>
      <powerStateRate>10.0</powerStateRate>
      <fullChargeCapacity>87.78</fullChargeCapacity>     
      <dischargeRate>-474</dischargeRate>
      <chargeRate>525</chargeRate>
      <dischargeVoltage>15.52</dischargeVoltage>
      <chargeVoltage>16.41</chargeVoltage>
    </plugin>
-->
  </gazebo>
  <!--
  Author: Felix Messmer
-->
  <link name="base_link">
    <inertial>
      <origin rpy="0 0 0" xyz="8.625E-08 -4.6583E-06 0.03145"/>
      <mass value="7.033"/>
      <inertia ixx="0.1478344" ixy="-0.00001" ixz="0.0" iyy="0.14782335" iyz="0.0" izz="0.29471799"/>
    </inertial>
    <visual>
      <origin rpy="0 0 0" xyz="0 0 0"/>
      <geometry>
        <mesh filename="package://mara_description/meshes/H-ROS_Robot_BASE.stl" scale="0.001 0.001 0.001"/>
      </geometry>
      <material name="Gazebo/Grey">
        <color rgba="0. 0. 0. 1"/>
      </material>
    </visual>
    <collision>
      <origin rpy="0 0 0" xyz="0 0 0"/>
      <geometry>
        <mesh filename="package://mara_description/meshes/H-ROS_Robot_BASE.stl" scale="0.001 0.001 0.001"/>
      </geometry>
    </collision>
  </link>
  <gazebo reference="base_link">
    <material>Gazebo/Grey</material>
    <selfCollide>False</selfCollide>
  </gazebo>
  <link name="motor1_link">
    <inertial>
      <origin rpy="0 0 0" xyz="8.625E-08 -4.6583E-06 0.03145"/>
      <mass value="5.8"/>
      <inertia ixx="0.10105893" ixy="0.000211" ixz="-0.004" iyy="0.09386624" iyz="-0.01698537" izz="0.01449937"/>
    </inertial>
    <visual>
      <origin rpy="0 0 0" xyz="0 0 0"/>
      <geometry>
        <mesh filename="package://mara_description/meshes/H-ROS_Robot_mara1.stl" scale="0.001 0.001 0.001"/>
      </geometry>
      <material name="Gazebo/White">
        <color rgba="0. 0. 0. 1"/>
      </material>
    </visual>
    <collision>
      <origin rpy="0 0 0" xyz="0 0 0"/>
      <geometry>
        <mesh filename="package://mara_description/meshes/H-ROS_Robot_mara1.stl" scale="0.001 0.001 0.001"/>
      </geometry>
    </collision>
  </link>
  <gazebo reference="motor1_link">
    <material>Gazebo/White</material>
    <selfCollide>False</selfCollide>
  </gazebo>
  <link name="motor2_link">
    <inertial>
      <origin rpy="0 0 0" xyz="8.625E-08 -4.6583E-06 0.03145"/>
      <mass value="1.03237"/>
      <inertia ixx="0.014865226" ixy="0.0" ixz="0.0" iyy="0.01557" iyz="0.00071" izz="0.00092"/>
    </inertial>
    <visual>
      <origin rpy="0 0 0" xyz="0 0 0"/>
      <geometry>
        <mesh filename="package://mara_description/meshes/H-ROS_Robot_LINK1.stl" scale="0.001 0.001 0.001"/>
      </geometry>
      <material name="Gazebo/Black">
        <color rgba="0. 0. 0. 1"/>
      </material>
    </visual>
    <collision>
      <origin rpy="0 0 0" xyz="0 0 0"/>
      <geometry>
        <mesh filename="package://mara_description/meshes/H-ROS_Robot_LINK1.stl" scale="0.001 0.001 0.001"/>
      </geometry>
    </collision>
  </link>
  <gazebo reference="motor2_link">
    <material>Gazebo/Black</material>
    <selfCollide>False</selfCollide>
  </gazebo>
  <link name="motor3_link">
    <inertial>
      <origin rpy="0 0 0" xyz="8.625E-08 -4.6583E-06 0.03145"/>
      <mass value="3.8"/>
      <inertia ixx="0.04517" ixy="0.00002" ixz="0.0" iyy="0.01587" iyz="0.01444" izz="0.03303"/>
    </inertial>
    <visual>
      <origin rpy="0 0 0" xyz="0 0 0"/>
      <geometry>
        <mesh filename="package://mara_description/meshes/H-ROS_Robot_mara2.stl" scale="0.001 0.001 0.001"/>
      </geometry>
      <material name="Gazebo/White">
        <color rgba="0. 0. 0. 1"/>
      </material>
    </visual>
    <collision>
      <origin rpy="0 0 0" xyz="0 0 0"/>
      <geometry>
        <mesh filename="package://mara_description/meshes/H-ROS_Robot_mara2.stl" scale="0.001 0.001 0.001"/>
      </geometry>
    </collision>
  </link>
  <gazebo reference="motor3_link">
    <material>Gazebo/White</material>
    <selfCollide>False</selfCollide>
  </gazebo>
  <link name="motor4_link">
    <inertial>
      <origin rpy="0 0 0" xyz="8.625E-08 -4.6583E-06 0.03145"/>
      <mass value="1.1"/>
      <inertia ixx="0.01464" ixy="0.0" ixz="0.0" iyy="0.00895" iyz="-0.00631" izz="0.00725"/>
    </inertial>
    <visual>
      <origin rpy="0 0 0" xyz="0 0 0"/>
      <geometry>
        <mesh filename="package://mara_description/meshes/H-ROS_Robot_LINK2.stl" scale="0.001 0.001 0.001"/>
      </geometry>
      <material name="Gazebo/Black">
        <color rgba="0. 0. 0. 1"/>
      </material>
    </visual>
    <collision>
      <origin rpy="0 0 0" xyz="0 0 0"/>
      <geometry>
        <mesh filename="package://mara_description/meshes/H-ROS_Robot_LINK2.stl" scale="0.001 0.001 0.001"/>
      </geometry>
    </collision>
  </link>
  <gazebo reference="motor4_link">
    <material>Gazebo/Black</material>
    <selfCollide>False</selfCollide>
  </gazebo>
  <link name="motor5_link">
    <inertial>
      <origin rpy="0 0 0" xyz="8.625E-08 -4.6583E-06 0.03145"/>
      <mass value="2.9"/>
      <inertia ixx="0.03406" ixy="0.0" ixz="0.0" iyy="0.01066" iyz="0.00989" izz="0.02563"/>
    </inertial>
    <visual>
      <origin rpy="0 0 0" xyz="0 0 0"/>
      <geometry>
        <mesh filename="package://mara_description/meshes/H-ROS_Robot_mara3.stl" scale="0.001 0.001 0.001"/>
      </geometry>
      <material name="Gazebo/White">
        <color rgba="0. 0. 0. 1"/>
      </material>
    </visual>
    <collision>
      <origin rpy="0 0 0" xyz="0 0 0"/>
      <geometry>
        <mesh filename="package://mara_description/meshes/H-ROS_Robot_mara3.stl" scale="0.001 0.001 0.001"/>
      </geometry>
    </collision>
  </link>
  <gazebo reference="motor5_link">
    <material>Gazebo/White</material>
    <selfCollide>False</selfCollide>
  </gazebo>
  <link name="motor6_link">
    <inertial>
      <origin rpy="0 0 0" xyz="8.625E-08 -4.6583E-06 0.03145"/>
      <mass value="2.9"/>
      <inertia ixx="0.0005" ixy="0.0" ixz="0.0" iyy="0.0005" iyz="0.0000" izz="0.0003"/>
    </inertial>
    <visual>
      <origin rpy="0 0 0" xyz="0 0 0"/>
      <geometry>
        <mesh filename="package://mara_description/meshes/gripper_support.stl" scale="0.001 0.001 0.001"/>
      </geometry>
      <material name="Gazebo/Black">
        <color rgba="0. 0. 0. 1"/>
      </material>
    </visual>
    <collision>
      <origin rpy="0 0 0" xyz="0 0 0"/>
      <geometry>
        <mesh filename="package://mara_description/meshes/gripper_support.stl" scale="0.001 0.001 0.001"/>
      </geometry>
    </collision>
  </link>
  <gazebo reference="motor6_link">
    <material>Gazebo/Black</material>
    <selfCollide>False</selfCollide>
  </gazebo>
  <link name="ee_link">
    <visual>
      <geometry>
        <box size="0.01 0.01 0.01"/>
      </geometry>
      <material name="Gazebo/Grey">
        <color rgba="0. 0. 0. 1"/>
      </material>
    </visual>
    <collision>
      <geometry>
        <box size="0.01 0.01 0.01"/>
      </geometry>
    </collision>
  </link>
  <gazebo reference="ee_link">
    <material>Gazebo/Blue</material>
    <selfCollide>False</selfCollide>
  </gazebo>
  <joint name="motor1" type="revolute">
    <origin rpy="0 0 0" xyz="0 0 0.00625"/>
    <parent link="base_link"/>
    <child link="motor1_link"/>
    <axis xyz="0 0 1"/>
    <limit effort="330.0" lower="-3.1416" upper="3.1416" velocity="2.16"/>
    <dynamics damping="0" friction="0"/>
  </joint>
  <joint name="motor2" type="revolute">
    <origin rpy="0 0 0" xyz="0 -0.100499999 0.1545"/>
    <parent link="motor1_link"/>
    <child link="motor2_link"/>
    <axis xyz="0 1 0"/>
    <limit effort="330.0" lower="-3.1416" upper="3.1416" velocity="2.16"/>
    <dynamics damping="0" friction="0"/>
  </joint>
  <joint name="motor3" type="revolute">
    <origin rpy="0 0 0" xyz="0 -0.000499999 0.2"/>
    <parent link="motor2_link"/>
    <child link="motor3_link"/>
    <axis xyz="0 1 0"/>
    <limit effort="150" lower="-3.1416" upper="3.1416" velocity="3.15"/>
    <dynamics damping="0" friction="0"/>
  </joint>
  <joint name="motor4" type="revolute">
    <origin rpy="0 0 0" xyz="0 0.09999 0.12999997"/>
    <parent link="motor3_link"/>
    <child link="motor4_link"/>
    <axis xyz="0 0 1"/>
    <limit effort="54" lower="-3.1416" upper="3.1416" velocity="3.2"/>
    <dynamics damping="0" friction="0"/>
  </joint>
  <joint name="motor5" type="revolute">
    <origin rpy="0 0 0" xyz="0 -0.096999 0.15906"/>
    <parent link="motor4_link"/>
    <child link="motor5_link"/>
    <axis xyz="0 1 0"/>
    <limit effort="54" lower="-3.1416" upper="3.1416" velocity="3.2"/>
    <dynamics damping="0" friction="0"/>
  </joint>
  <joint name="motor6" type="revolute">
    <origin rpy="0 0 0" xyz="0 0.097 0.12"/>
    <parent link="motor5_link"/>
    <child link="motor6_link"/>
    <axis xyz="0 0 1"/>
    <limit effort="54" lower="-3.1416" upper="3.1416" velocity="3.2"/>
    <dynamics damping="0" friction="0"/>
  </joint>
  <joint name="ee_link" type="fixed">
    <origin rpy="0 -1.57 0" xyz="0 0.0 0.21"/>
    <parent link="motor6_link"/>
    <child link="ee_link"/>
  </joint>
  <transmission name="shoulder_pan_trans">
    <type>transmission_interface/SimpleTransmission</type>
    <joint name="motor1">
      <hardwareInterface>hardware_interface/PositionJointInterface</hardwareInterface>
    </joint>
    <actuator name="shoulder_pan_motor">
      <mechanicalReduction>1</mechanicalReduction>
    </actuator>
  </transmission>
  <transmission name="shoulder_lift_trans">
    <type>transmission_interface/SimpleTransmission</type>
    <joint name="motor2">
      <hardwareInterface>hardware_interface/PositionJointInterface</hardwareInterface>
    </joint>
    <actuator name="shoulder_lift_motor">
      <mechanicalReduction>1</mechanicalReduction>
    </actuator>
  </transmission>
  <transmission name="elbow_trans">
    <type>transmission_interface/SimpleTransmission</type>
    <joint name="motor3">
      <hardwareInterface>hardware_interface/PositionJointInterface</hardwareInterface>
    </joint>
    <actuator name="elbow_motor">
      <mechanicalReduction>1</mechanicalReduction>
    </actuator>
  </transmission>
  <transmission name="wrist_1_trans">
    <type>transmission_interface/SimpleTransmission</type>
    <joint name="motor4">
      <hardwareInterface>hardware_interface/PositionJointInterface</hardwareInterface>
    </joint>
    <actuator name="wrist_1_motor">
      <mechanicalReduction>1</mechanicalReduction>
    </actuator>
  </transmission>
  <transmission name="wrist_2_trans">
    <type>transmission_interface/SimpleTransmission</type>
    <joint name="motor5">
      <hardwareInterface>hardware_interface/PositionJointInterface</hardwareInterface>
    </joint>
    <actuator name="wrist_2_motor">
      <mechanicalReduction>1</mechanicalReduction>
    </actuator>
  </transmission>
  <transmission name="wrist_3_trans">
    <type>transmission_interface/SimpleTransmission</type>
    <joint name="motor6">
      <hardwareInterface>hardware_interface/PositionJointInterface</hardwareInterface>
    </joint>
    <actuator name="wrist_3_motor">
      <mechanicalReduction>1</mechanicalReduction>
    </actuator>
  </transmission>
  <!-- nothing to do here at the moment -->
  <!-- ROS ${prefix}base_link to UR 'Base' Coordinates transform -->
  <link name="base"/>
  <joint name="base_link-base_fixed_joint" type="fixed">
    <!-- NOTE: this rotation is only needed as long as ${prefix}base_link itself is
                 not corrected wrt the real robot (ie: rotated over 180
                 degrees)
      -->
    <origin rpy="0 0 -3.14159265359" xyz="0 0 0"/>
    <parent link="base_link"/>
    <child link="base"/>
  </joint>
  <!-- Frame coincident with all-zeros TCP on UR controller -->
  <link name="tool0"/>
  <joint name="motor6_link-tool0_fixed_joint" type="fixed">
    <origin rpy="-1.57079632679 0 0" xyz="0 0 0"/>
    <parent link="motor6_link"/>
    <child link="tool0"/>
  </joint>
  <link name="robotiq_arg2f_base_link">
    <inertial>
      <origin rpy="0 0 0" xyz="8.625E-08 -4.6583E-06 0.03145"/>
      <mass value="0.22652"/>
      <inertia ixx="0.00020005" ixy="-4.2442E-10" ixz="-2.9069E-10" iyy="0.00017832" iyz="-3.4402E-08" izz="0.00013478"/>
    </inertial>
    <visual>
      <origin rpy="0 0 0" xyz="0 0 0"/>
      <geometry>
        <mesh filename="package://robotiq_arg2f_model_visualization/meshes/GRIPPER_base_axis.stl" scale="0.001 0.001 0.001"/>
      </geometry>
      <material name="">
        <color rgba="0.1 0.1 0.1 1"/>
      </material>
    </visual>
    <collision>
      <origin rpy="0 0 0" xyz="0 0 0"/>
      <geometry>
        <mesh filename="package://robotiq_arg2f_model_visualization/meshes/GRIPPER_base_axis.stl" scale="0.001 0.001 0.001"/>
      </geometry>
    </collision>
  </link>
  <gazebo reference="robotiq_arg2f_base_link">
    <material>Gazebo/Grey</material>
    <selfCollide>False</selfCollide>
  </gazebo>
  <link name="left_outer_knuckle">
    <inertial>
      <origin rpy="0 0 0" xyz="-0.000200000000003065 0.0199435877845359 0.0292245259211331"/>
      <mass value="0.00853198276973456"/>
      <inertia ixx="2.89328108496468E-06" ixy="-1.57935047237397E-19" ixz="-1.93980378593255E-19" iyy="1.86719750325683E-06" iyz="-1.21858577871576E-06" izz="1.21905238907251E-06"/>
    </inertial>
    <visual>
      <origin rpy="0 0 0" xyz="0 0 0"/>
      <geometry>
        <mesh filename="package://robotiq_arg2f_model_visualization/meshes/robotiq_arg2f_140_outer_knuckle.stl"/>
      </geometry>
      <material name="">
        <color rgba="0.792156862745098 0.819607843137255 0.933333333333333 1"/>
      </material>
    </visual>
    <collision>
      <origin rpy="0 0 0" xyz="0 0 0"/>
      <geometry>
        <mesh filename="package://robotiq_arg2f_model_visualization/meshes/robotiq_arg2f_140_outer_knuckle.stl"/>
      </geometry>
    </collision>
  </link>
  <gazebo reference="left_outer_knuckle">
    <material>Gazebo/Grey</material>
    <selfCollide>False</selfCollide>
  </gazebo>
  <link name="right_outer_knuckle">
    <inertial>
      <origin rpy="0 0 0" xyz="-0.000200000000003065 0.0199435877845359 0.0292245259211331"/>
      <mass value="0.00853198276973456"/>
      <inertia ixx="2.89328108496468E-06" ixy="-1.57935047237397E-19" ixz="-1.93980378593255E-19" iyy="1.86719750325683E-06" iyz="-1.21858577871576E-06" izz="1.21905238907251E-06"/>
    </inertial>
    <visual>
      <origin rpy="0 0 0" xyz="0 0 0"/>
      <geometry>
        <mesh filename="package://robotiq_arg2f_model_visualization/meshes/robotiq_arg2f_140_outer_knuckle.stl"/>
      </geometry>
      <material name="">
        <color rgba="0.792156862745098 0.819607843137255 0.933333333333333 1"/>
      </material>
    </visual>
    <collision>
      <origin rpy="0 0 0" xyz="0 0 0"/>
      <geometry>
        <mesh filename="package://robotiq_arg2f_model_visualization/meshes/robotiq_arg2f_140_outer_knuckle.stl"/>
      </geometry>
    </collision>
  </link>
  <gazebo reference="right_outer_knuckle">
    <material>Gazebo/Grey</material>
    <selfCollide>False</selfCollide>
  </gazebo>
  <link name="left_inner_knuckle">
    <inertial>
      <origin rpy="0 0 0" xyz="0.000123011831763771 0.0507850843201817 0.00103968640075166"/>
      <mass value="0.0271177346495152"/>
      <inertia ixx="2.61910379223783E-05" ixy="-2.43616858946494E-07" ixz="-6.37789906117123E-09" iyy="2.8270243746167E-06" iyz="-5.37200748039765E-07" izz="2.83695868220296E-05"/>
    </inertial>
    <visual>
      <origin rpy="0 0 0" xyz="0 0 0"/>
      <geometry>
        <mesh filename="package://robotiq_arg2f_model_visualization/meshes/robotiq_arg2f_140_inner_knuckle.stl"/>
      </geometry>
      <material name="">
        <color rgba="0.1 0.1 0.1 1"/>
      </material>
    </visual>
    <collision>
      <origin rpy="0 0 0" xyz="0 0 0"/>
      <geometry>
        <mesh filename="package://robotiq_arg2f_model_visualization/meshes/robotiq_arg2f_140_inner_knuckle.stl"/>
      </geometry>
    </collision>
  </link>
  <gazebo reference="left_inner_knuckle">
    <material>Gazebo/Grey</material>
    <selfCollide>False</selfCollide>
  </gazebo>
  <link name="right_inner_knuckle">
    <inertial>
      <origin rpy="0 0 0" xyz="0.000123011831763771 0.0507850843201817 0.00103968640075166"/>
      <mass value="0.0271177346495152"/>
      <inertia ixx="2.61910379223783E-05" ixy="-2.43616858946494E-07" ixz="-6.37789906117123E-09" iyy="2.8270243746167E-06" iyz="-5.37200748039765E-07" izz="2.83695868220296E-05"/>
    </inertial>
    <visual>
      <origin rpy="0 0 0" xyz="0 0 0"/>
      <geometry>
        <mesh filename="package://robotiq_arg2f_model_visualization/meshes/robotiq_arg2f_140_inner_knuckle.stl"/>
      </geometry>
      <material name="">
        <color rgba="0.1 0.1 0.1 1"/>
      </material>
    </visual>
    <collision>
      <origin rpy="0 0 0" xyz="0 0 0"/>
      <geometry>
        <mesh filename="package://robotiq_arg2f_model_visualization/meshes/robotiq_arg2f_140_inner_knuckle.stl"/>
      </geometry>
    </collision>
  </link>
  <gazebo reference="right_inner_knuckle">
    <material>Gazebo/Grey</material>
    <selfCollide>False</selfCollide>
  </gazebo>
  <link name="left_inner_finger">
    <inertial>
      <origin rpy="0 0 0" xyz="0.000299999999999317 0.0160078233491243 -0.0136945669206257"/>
      <mass value="0.0104003125914103"/>
      <inertia ixx="2.71909453810972E-06" ixy="1.35402465472579E-21" ixz="-7.1817349065269E-22" iyy="7.69100314106116E-07" iyz="6.74715432769696E-07" izz="2.30315190420171E-06"/>
    </inertial>
    <visual>
      <origin rpy="0 0 0" xyz="0 0 0"/>
      <geometry>
        <mesh filename="package://robotiq_arg2f_model_visualization/meshes/robotiq_arg2f_140_inner_finger.stl"/>
      </geometry>
      <material name="">
        <color rgba="0.1 0.1 0.1 1"/>
      </material>
    </visual>
    <collision>
      <origin rpy="0 0 0" xyz="0 0 0"/>
      <geometry>
        <mesh filename="package://robotiq_arg2f_model_visualization/meshes/robotiq_arg2f_140_inner_finger.stl"/>
      </geometry>
    </collision>
  </link>
  <gazebo reference="left_inner_finger">
    <material>Gazebo/Grey</material>
    <selfCollide>False</selfCollide>
  </gazebo>
  <link name="right_inner_finger">
    <inertial>
      <origin rpy="0 0 0" xyz="0.000299999999999317 0.0160078233491243 -0.0136945669206257"/>
      <mass value="0.0104003125914103"/>
      <inertia ixx="2.71909453810972E-06" ixy="1.35402465472579E-21" ixz="-7.1817349065269E-22" iyy="7.69100314106116E-07" iyz="6.74715432769696E-07" izz="2.30315190420171E-06"/>
    </inertial>
    <visual>
      <origin rpy="0 0 0" xyz="0 0 0"/>
      <geometry>
        <mesh filename="package://robotiq_arg2f_model_visualization/meshes/robotiq_arg2f_140_inner_finger.stl"/>
      </geometry>
      <material name="">
        <color rgba="0.1 0.1 0.1 1"/>
      </material>
    </visual>
    <collision>
      <origin rpy="0 0 0" xyz="0 0 0"/>
      <geometry>
        <mesh filename="package://robotiq_arg2f_model_visualization/meshes/robotiq_arg2f_140_inner_finger.stl"/>
      </geometry>
    </collision>
  </link>
  <gazebo reference="right_inner_finger">
    <material>Gazebo/Grey</material>
    <selfCollide>False</selfCollide>
  </gazebo>
  <link name="left_outer_finger">
    <inertial>
      <origin rpy="0 0 0" xyz="0.00030115855001899 0.0373907951953854 -0.0208027427000385"/>
      <mass value="0.022614240507152"/>
      <inertia ixx="1.52518312458174E-05" ixy="9.76583423954399E-10" ixz="-5.43838577022588E-10" iyy="6.17694243867776E-06" iyz="6.78636130740228E-06" izz="1.16494917907219E-05"/>
    </inertial>
    <visual>
      <origin rpy="0 0 0" xyz="0 0 0"/>
      <geometry>
        <mesh filename="package://robotiq_arg2f_model_visualization/meshes/robotiq_arg2f_140_outer_finger.stl"/>
      </geometry>
      <material name="">
        <color rgba="0.1 0.1 0.1 1"/>
      </material>
    </visual>
    <collision>
      <origin rpy="0 0 0" xyz="0 0 0"/>
      <geometry>
        <mesh filename="package://robotiq_arg2f_model_visualization/meshes/robotiq_arg2f_140_outer_finger.stl"/>
      </geometry>
    </collision>
  </link>
  <gazebo reference="left_outer_finger">
    <material>Gazebo/Grey</material>
    <selfCollide>False</selfCollide>
  </gazebo>
  <link name="right_outer_finger">
    <inertial>
      <origin rpy="0 0 0" xyz="0.00030115855001899 0.0373907951953854 -0.0208027427000385"/>
      <mass value="0.022614240507152"/>
      <inertia ixx="1.52518312458174E-05" ixy="9.76583423954399E-10" ixz="-5.43838577022588E-10" iyy="6.17694243867776E-06" iyz="6.78636130740228E-06" izz="1.16494917907219E-05"/>
    </inertial>
    <visual>
      <origin rpy="0 0 0" xyz="0 0 0"/>
      <geometry>
        <mesh filename="package://robotiq_arg2f_model_visualization/meshes/robotiq_arg2f_140_outer_finger.stl"/>
      </geometry>
      <material name="">
        <color rgba="0.1 0.1 0.1 1"/>
      </material>
    </visual>
    <collision>
      <origin rpy="0 0 0" xyz="0 0 0"/>
      <geometry>
        <mesh filename="package://robotiq_arg2f_model_visualization/meshes/robotiq_arg2f_140_outer_finger.stl"/>
      </geometry>
    </collision>
  </link>
  <gazebo reference="right_outer_finger">
    <material>Gazebo/Grey</material>
    <selfCollide>False</selfCollide>
  </gazebo>
  <joint name="left_outer_knuckle_joint" type="revolute">
    <origin rpy="2.29579632679 0 1.57" xyz="0.030601 0 0.050905"/>
    <parent link="robotiq_arg2f_base_link"/>
    <child link="left_outer_knuckle"/>
    <axis xyz="-1 0 0"/>
    <limit effort="0" lower="0" upper="2" velocity="0.0"/>
  </joint>
  <joint name="right_outer_knuckle_joint" type="revolute">
    <origin rpy="2.29579632679 0 4.71" xyz="-0.030601 0 0.050905"/>
    <parent link="robotiq_arg2f_base_link"/>
    <child link="right_outer_knuckle"/>
    <axis xyz="-1 0 0"/>
    <limit effort="0" lower="0" upper="2" velocity="0.0"/>
  </joint>
  <joint name="left_inner_knuckle_joint" type="revolute">
    <origin rpy="2.29579632679 0 1.57" xyz="0.0127 0 0.05642"/>
    <parent link="robotiq_arg2f_base_link"/>
    <child link="left_inner_knuckle"/>
    <axis xyz="-1 0 0"/>
    <limit effort="100" lower="0" upper="0.7" velocity="0.1"/>
  </joint>
  <joint name="right_inner_knuckle_joint" type="revolute">
    <origin rpy="2.29579632679 0 4.71" xyz="-0.0127 0 0.05642"/>
    <parent link="robotiq_arg2f_base_link"/>
    <child link="right_inner_knuckle"/>
    <axis xyz="-1 0 0"/>
    <limit effort="100" lower="0" upper="0.7" velocity="0.1"/>
  </joint>
  <joint name="left_outer_finger_joint" type="revolute">
    <origin rpy="0 0 0" xyz="0 0.01821998610742 0.0260018192872234"/>
    <parent link="left_outer_knuckle"/>
    <child link="left_outer_finger"/>
    <axis xyz="-1 0 0"/>
    <limit effort="1000" lower="-2" upper="2" velocity="2.0"/>
  </joint>
  <joint name="right_outer_finger_joint" type="revolute">
    <origin rpy="0 0 0" xyz="0 0.01821998610742 0.0260018192872234"/>
    <parent link="right_outer_knuckle"/>
    <child link="right_outer_finger"/>
    <axis xyz="-1 0 0"/>
    <limit effort="1000" lower="-2" upper="2" velocity="2.0"/>
  </joint>
  <joint name="left_inner_finger_joint" type="revolute">
    <origin rpy="-.725 0 0" xyz="0 0.0817554015893473 -0.0282203446692936"/>
    <parent link="left_outer_finger"/>
    <child link="left_inner_finger"/>
    <axis xyz="-1 0 0"/>
    <limit effort="1000" lower="-2" upper="2" velocity="2.0"/>
  </joint>
  <joint name="right_inner_finger_joint" type="revolute">
    <origin rpy="-.725 0 0" xyz="0 0.0817554015893473 -0.0282203446692936"/>
    <parent link="right_outer_finger"/>
    <child link="right_inner_finger"/>
    <axis xyz="-1 0 0"/>
    <limit effort="1000" lower="-2" upper="2" velocity="2.0"/>
  </joint>
  <gazebo>
    <joint name="left_inner_finger_knuckle_joint" type="revolute">
      <pose frame="">0 0.006 -0.018 0 0 0</pose>
      <parent>robot::left_inner_knuckle</parent>
      <child>robot::left_inner_finger</child>
      <axis>
        <xyz>0 0 -1</xyz>
        <limit>
          <lower>-0.6</lower>
          <upper>0.6</upper>
          <velocity>0</velocity>
          <effort>0</effort>
        </limit>
      </axis>
    </joint>
    <joint name="right_inner_finger_knuckle_joint" type="revolute">
      <pose frame="">0 0.006 -0.018 0 0 0</pose>
      <parent>robot::right_inner_knuckle</parent>
      <child>robot::right_inner_finger</child>
      <axis>
        <xyz>0 0 -1</xyz>
        <limit>
          <lower>-0.6</lower>
          <upper>0.6</upper>
          <velocity>0</velocity>
          <effort>0</effort>
        </limit>
      </axis>
    </joint>
    <plugin filename="libRobotiq140Plugin.so" name="robotiq_arg2f_gazebo_plugins"/>
    <plugin filename="libgazebo_grasp_fix.so" name="gazebo_grasp_fix">
      <arm>
        <arm_name>robot</arm_name>
        <palm_link>left_inner_finger</palm_link>
        <gripper_link>left_inner_finger</gripper_link>
        <gripper_link>right_inner_finger</gripper_link>
        <gripper_link>left_inner_knuckle</gripper_link>
        <gripper_link>right_inner_knuckle</gripper_link>
      </arm>
      <forces_angle_tolerance>100</forces_angle_tolerance>
      <update_rate>4</update_rate>
      <grip_count_threshold>4</grip_count_threshold>
      <max_grip_count>8</max_grip_count>
      <release_tolerance>0.5</release_tolerance>
      <disable_collisions_on_attach>false</disable_collisions_on_attach>
      <contact_topic>__default_topic__</contact_topic>
    </plugin>
  </gazebo>
  <link name="mara_work_area_link">
    <inertial>
      <origin rpy="0 0 0" xyz="8.625E-08 -4.6583E-06 0.03145"/>
      <mass value="7.033"/>
      <inertia ixx="0.1478344" ixy="-0.00001" ixz="0.0" iyy="0.14782335" iyz="0.0" izz="0.29471799"/>
    </inertial>
    <visual>
      <origin rpy="0 0 0" xyz="0 0 0"/>
      <geometry>
        <mesh filename="package://mara_description/meshes/demo/AIR_WorkArea.stl" scale="0.001 0.001 0.001"/>
      </geometry>
      <material name="Gazebo/Wood">
        <color rgba="0. 0. 0. 1"/>
      </material>
    </visual>
    <collision>
      <origin rpy="0 0 0" xyz="0 0 0"/>
      <geometry>
        <mesh filename="package://mara_description/meshes/demo/AIR_WorkArea.stl" scale="0.001 0.001 0.001"/>
      </geometry>
    </collision>
  </link>
  <gazebo reference="mara_work_area_link">
    <material>Gazebo/Wood</material>
    <selfCollide>False</selfCollide>
  </gazebo>
  <link name="mara_camera_support_link">
    <inertial>
      <origin rpy="0 0 0" xyz="8.625E-08 -4.6583E-06 0.03145"/>
      <mass value="7.033"/>
      <inertia ixx="0.1478344" ixy="-0.00001" ixz="0.0" iyy="0.14782335" iyz="0.0" izz="0.29471799"/>
    </inertial>
    <visual>
      <origin rpy="0 0 0" xyz="0 0 0"/>
      <geometry>
        <mesh filename="package://mara_description/meshes/demo/top/top_camera_support.stl" scale="0.001 0.001 0.001"/>
      </geometry>
      <material name="Gazebo/Wood">
        <color rgba="0. 0. 0. 1"/>
      </material>
    </visual>
    <collision>
      <origin rpy="0 0 0" xyz="0 0 0"/>
      <geometry>
        <mesh filename="package://mara_description/meshes/demo/top/top_camera_support.stl" scale="0.001 0.001 0.001"/>
      </geometry>
    </collision>
  </link>
  <gazebo reference="mara_work_area_link">
    <material>Gazebo/Wood</material>
    <selfCollide>False</selfCollide>
  </gazebo>
  <link name="depthsensor">
    <inertial>
      <origin rpy="0 0 0" xyz="-0.12987 0 0.02947"/>
      <mass value="10.0"/>
      <inertia ixx="1.38185" ixy="-0.00001" ixz="-0.05685" iyx="-0.00001" iyy="1.03177" iyz="0.0" izx="-0.05685" izy="0.00000" izz="2.27567"/>
    </inertial>
    <visual>
      <origin rpy="0 0 0" xyz="0 0 0"/>
      <geometry>
        <mesh filename="package://scara_e1_description/meshes/camera/SCARA_DepthSensor_SIDE.stl" scale="0.001 0.001 0.001"/>
      </geometry>
      <material name="Gazebo/Grey">
        <color rgba="1. 1. 1. 1"/>
      </material>
    </visual>
  </link>
  <gazebo reference="depthsensor">
    <material>Gazebo/Grey</material>
    <selfCollide>False</selfCollide>
  </gazebo>
  <link name="camera"/>
  <joint name="base_to_work_area_joint" type="fixed">
    <origin rpy="0 0 0" xyz="-0.450 0 0.00625"/>
    <parent link="base_link"/>
    <child link="mara_work_area_link"/>
  </joint>
  <joint name="base_to_camera_support_joint" type="fixed">
    <origin rpy="0 0 3.1416" xyz="-0.6 0 0.43125"/>
    <parent link="base_link"/>
    <child link="mara_camera_support_link"/>
  </joint>
  <joint name="camera_adapter_to_camera" type="fixed">
    <origin rpy="0 1.57 3.1416" xyz="-0.081188216 0.018 0.434548906"/>
    <parent link="mara_camera_support_link"/>
    <child link="depthsensor"/>
  </joint>
  <joint name="camera_joint" type="fixed">
    <origin rpy="0 0 0" xyz="0.055 0.031375 0.01"/>
    <parent link="depthsensor"/>
    <child link="camera"/>
  </joint>
  <gazebo reference="camera">
    <sensor name="camera_sensor" type="camera">
      <update_rate>20</update_rate>
      <camera>
        <horizontal_fov>1.01</horizontal_fov>
        <image>
          <format>R8G8B8</format>
          <width>320</width>
          <height>240</height>
        </image>
        <clip>
          <near>0.01</near>
          <far>2.0</far>
        </clip>
      </camera>
      <visualize>true</visualize>
      <plugin filename="libgazebo_ros_camera.so" name="camera_camera_controller">
        <cameraName>/mara/camera</cameraName>
        <alwaysOn>true</alwaysOn>
        <updateRate>20</updateRate>
        <visualize>true</visualize>
        <imageTopicName>image_raw</imageTopicName>
        <cameraInfoTopicName>camera_info</cameraInfoTopicName>
        <frameName>camera</frameName>
      </plugin>
    </sensor>
  </gazebo>
  <link name="table">
    <contact>
      <lateral_friction value="1.0"/>
    </contact>
    <inertial>
      <origin rpy="0 0 0" xyz="0 0 0"/>
      <mass value=".0"/>
      <inertia ixx="1" ixy="0" ixz="0" iyy="1" iyz="0" izz="1"/>
    </inertial>
    <visual>
      <origin rpy="0 0 0" xyz="0 0 0.6"/>
      <geometry>
        <mesh filename="package://mara_description/urdf/table.obj" scale="1.5 1 0.05"/>
      </geometry>
      <material name="white">
        <color rgba="1 1 1 1"/>
      </material>
    </visual>
    <collision>
      <origin rpy="0 0 0" xyz="0 0 0.6"/>
      <geometry>
        <box size="1.5 1 0.05"/>
      </geometry>
    </collision>
    <visual>
      <origin rpy="0 0 0" xyz="-0.65 -0.4 0.29"/>
      <geometry>
        <mesh filename="package://mara_description/urdf/table.obj" scale="0.1 0.1 0.58"/>
      </geometry>
      <material name="framemat0"/>
    </visual>
    <visual>
      <origin rpy="0 0 0" xyz="-0.65 0.4 0.29"/>
      <geometry>
        <mesh filename="package://mara_description/urdf/table.obj" scale="0.1 0.1 0.58"/>
      </geometry>
      <material name="framemat0"/>
    </visual>
    <visual>
      <origin rpy="0 0 0" xyz="0.65 -0.4 0.29"/>
      <geometry>
        <mesh filename="package://mara_description/urdf/table.obj" scale="0.1 0.1 0.58"/>
      </geometry>
      <material name="framemat0"/>
    </visual>
    <visual>
      <origin rpy="0 0 0" xyz="0.65 0.4 0.29"/>
      <geometry>
        <mesh filename="package://mara_description/urdf/table.obj" scale="0.1 0.1 0.58"/>
      </geometry>
    </visual>
  </link>
  <link name="world"/>
  <joint name="end_effector_adapter_to_robotiq" type="fixed">
    <origin rpy="0 0 1.57" xyz=" 0 0 0.065"/>
    <parent link="motor6_link"/>
    <child link="robotiq_arg2f_base_link"/>
  </joint>
  <joint name="world_to_table_joint" type="fixed">
    <origin rpy="0 0 0" xyz="0 0 0.02"/>
    <parent link="world"/>
    <child link="table"/>
  </joint>
  <joint name="table_to_base_joint" type="fixed">
    <origin rpy="0 0 0" xyz="0 0 0.65"/>
    <parent link="table"/>
    <child link="base_link"/>
  </joint>
</robot>

